<?xml version='1.0'?>
<robot name="simple_claw_robot">

    <!-- Wood Base Link [0] -->
    <link name="Base_Wood">
        <inertial>
            <mass value="1.0"/>  <!-- Mass in kilograms -->
            <origin xyz="0 0 0" rpy="0 0 0"/>  <!-- Center of mass position (relative to link frame) -->
            <inertia ixx="0.01" ixy="0.0" ixz="0.0" iyy="0.01" iyz="0.0" izz="0.01"/>  <!-- Inertia matrix -->
        </inertial>
        <visual>
            <geometry>
                <mesh filename="Base_Wood.obj"/>
            </geometry>
            <material name="dark_gray">
                <color rgba="0.4 0.4 0.4 1.0"/>
            </material>
        </visual>
        <collision>
            <geometry>
                <mesh filename="Base_Wood.obj"/>
            </geometry>
        </collision>
    </link>

    <!-- Metal Base Link [1] -->
    <link name="Base_Metal">
        <inertial>
            <mass value="0.15"/>  <!-- Mass in kilograms -->
            <origin xyz="0 0 0" rpy="0 0 0"/>  <!-- Center of mass position (relative to link frame) -->
            <inertia ixx="0.01" ixy="0.0" ixz="0.0" iyy="0.01" iyz="0.0" izz="0.01"/>  <!-- Inertia matrix -->
        </inertial>
        <visual>
            <geometry>
                <mesh filename="Base_Metal.obj"/>
            </geometry>
            <material name="dark_gray">
                <color rgba="0.4 0.4 0.4 1.0"/>
            </material>
        </visual>
        <collision>
            <geometry>
                <mesh filename="Base_Metal.obj"/>
            </geometry>
        </collision>
    </link>

    <!-- Joint connecting wood to metal base does not move [0] -->
    <joint name="WoodtoMetal" type="fixed">
        <parent link="Base_Wood"/>
        <child link="Base_Metal"/>
        <origin xyz="0 0 0.0225" rpy="0 0 0"/>
    </joint>

    <!-- Servo Base Link [2] -->
    <link name="Servo_Base">
        <inertial>
            <mass value="0.055"/>  <!-- Mass in kilograms -->
            <origin xyz="0 0 0" rpy="0 0 0"/>  <!-- Center of mass position (relative to link frame) -->
            <inertia ixx="0.01" ixy="0.0" ixz="0.0" iyy="0.01" iyz="0.0" izz="0.01"/>  <!-- Inertia matrix -->
        </inertial>
        <visual>
            <geometry>
                <mesh filename="Servo_Base.obj"/>
            </geometry>
            <material name="dark_gray">
                <color rgba="0.4 0.4 0.4 1.0"/>
            </material>
        </visual>
        <collision>
            <geometry>
                <mesh filename="Servo_Base.obj"/>
            </geometry>
        </collision>
    </link>

    <!-- Joint connectiong Metal base to servo does not move [1] -->
    <joint name="MetaltoServo" type="fixed">
        <parent link="Base_Metal"/>
        <child link="Servo_Base"/>
        <origin xyz="0 0 0.041" rpy="0 0 0"/>
    </joint>

    <!-- Servo Shoulder Link [3] -->
    <link name="Servo_Shoulder">
        <inertial>
            <mass value="0.055"/>  <!-- Mass in kilograms -->
            <origin xyz="0 0 0" rpy="0 0 0"/>  <!-- Center of mass position (relative to link frame) -->
            <inertia ixx="0.01" ixy="0.0" ixz="0.0" iyy="0.01" iyz="0.0" izz="0.01"/>  <!-- Inertia matrix -->
        </inertial>
        <visual>
            <geometry>
                <mesh filename="Servo_Shoulder.obj"/>
            </geometry>
            <material name="dark_gray">
                <color rgba="0.4 0.4 0.4 1.0"/>
            </material>
        </visual>
        <collision>
            <geometry>
                <mesh filename="Servo_Shoulder.obj"/>
            </geometry>
        </collision>
    </link>

    <!-- Joint connectiong Base Servo to Shoulder servo [2] -->
    <joint name="BasetoShoulder" type="revolute">
        <parent link="Servo_Base"/>
        <child link="Servo_Shoulder"/>
        <origin xyz="0 0 0.03825" rpy="0 0 0"/>
        <axis xyz="0.0 0.0 1.0"/>
        <limit lower="-1.57" upper="1.57" effort="1.0" velocity="1.0"/>
    </joint>

    <!-- H Bracket Link [4] -->
    <link name="Bracket_H">
        <inertial>
            <mass value="0.044"/>  <!-- Mass in kilograms -->
            <origin xyz="0 0 0" rpy="0 0 0"/>  <!-- Center of mass position (relative to link frame) -->
            <inertia ixx="0.01" ixy="0.0" ixz="0.0" iyy="0.01" iyz="0.0" izz="0.01"/>  <!-- Inertia matrix -->
        </inertial>
        <visual>
            <geometry>
                <mesh filename="Bracket_H.obj"/>
            </geometry>
            <material name="dark_gray">
                <color rgba="0.4 0.4 0.4 1.0"/>
            </material>
        </visual>
        <collision>
            <geometry>
                <mesh filename="Bracket_H.obj"/>
            </geometry>
        </collision>
    </link>

    <!-- Joint connectiong Shoulder Servo to H Bracket pitchs up and down [3] -->
    <joint name="ShouldertoBracket" type="revolute">
        <parent link="Servo_Shoulder"/>
        <child link="Bracket_H"/>
        <origin xyz="0 0 0" rpy="0 0 0"/>
        <axis xyz="1.0 0.0 0.0"/>
        <limit lower="-1.57" upper="1.57" effort="100.0" velocity="0.0"/>
    </joint>

    <!-- Servo Elbow Link [5] -->
    <link name="Servo_Elbow">
        <inertial>
            <mass value="0.055"/>  <!-- Mass in kilograms -->
            <origin xyz="0 0 0" rpy="0 0 0"/>  <!-- Center of mass position (relative to link frame) -->
            <inertia ixx="0.01" ixy="0.0" ixz="0.0" iyy="0.01" iyz="0.0" izz="0.01"/>  <!-- Inertia matrix -->
        </inertial>
        <visual>
            <geometry>
                <mesh filename="Servo_Elbow.obj"/>
            </geometry>
            <material name="dark_gray">
                <color rgba="0.4 0.4 0.4 1.0"/>
            </material>
        </visual>
        <collision>
            <geometry>
                <mesh filename="Servo_Elbow.obj"/>
            </geometry>
        </collision>
    </link>

    <!-- Joint connectiong H Bracket to Elbow pitches [4] -->
    <joint name="BrackettoElbow" type="revolute">
        <parent link="Bracket_H"/>
        <child link="Servo_Elbow"/>
        <origin xyz="0 0 0.105" rpy="0 0 0"/>
        <axis xyz="1.0 0.0 0.0"/>
        <limit lower="-1.57" upper="1.57" effort="1.0" velocity="1.0"/>
    </joint>

    <!-- Forearm Connector Link [6] -->
    <link name="Connector_Forearm">
        <inertial>
            <mass value="0.043"/>  <!-- Mass in kilograms -->
            <origin xyz="0 0 0" rpy="0 0 0"/>  <!-- Center of mass position (relative to link frame) -->
            <inertia ixx="0.01" ixy="0.0" ixz="0.0" iyy="0.01" iyz="0.0" izz="0.01"/>  <!-- Inertia matrix -->
        </inertial>
        <visual>
            <geometry>
                <mesh filename="Connector_Forearm.obj"/>
            </geometry>
            <material name="dark_gray">
                <color rgba="0.4 0.4 0.4 1.0"/>
            </material>
        </visual>
        <collision>
            <geometry>
                <mesh filename="Connector_Forearm.obj"/>
            </geometry>
        </collision>
    </link>

    <!-- Joint connectiong Elbow Servo to Forearm Connector does not move [5] -->
    <joint name="ElbowtoForearm" type="fixed">
        <parent link="Servo_Elbow"/>
        <child link="Connector_Forearm"/>
        <origin xyz="0 0 0.0475" rpy="0 0 0"/>
    </joint>

    <!-- Servo Wrist Pitch Link [7] -->
    <link name="Servo_WristPitch">
        <inertial>
            <mass value="0.055"/>  <!-- Mass in kilograms -->
            <origin xyz="0 0 0" rpy="0 0 0"/>  <!-- Center of mass position (relative to link frame) -->
            <inertia ixx="0.01" ixy="0.0" ixz="0.0" iyy="0.01" iyz="0.0" izz="0.01"/>  <!-- Inertia matrix -->
        </inertial>
        <visual>
            <geometry>
                <mesh filename="Servo_WristPitch.obj"/>
            </geometry>
            <material name="dark_gray">
                <color rgba="0.4 0.4 0.4 1.0"/>
            </material>
        </visual>
        <collision>
            <geometry>
                <mesh filename="Servo_WristPitch.obj"/>
            </geometry>
        </collision>
    </link>

    <!-- Joint connectiong Forearm Connector to Wrist Pitch Servo does not move [6] -->
    <joint name="ForearmtoWristP" type="fixed">
        <parent link="Connector_Forearm"/>
        <child link="Servo_WristPitch"/>
        <origin xyz="0 0 0.0775" rpy="0 0 0"/>
    </joint>

    <!-- U Bracket Link [8] -->
    <link name="Bracket_U">
        <inertial>
            <mass value="0.022"/>  <!-- Mass in kilograms -->
            <origin xyz="0 0 0" rpy="0 0 0"/>  <!-- Center of mass position (relative to link frame) -->
            <inertia ixx="0.01" ixy="0.0" ixz="0.0" iyy="0.01" iyz="0.0" izz="0.01"/>  <!-- Inertia matrix -->
        </inertial>
        <visual>
            <geometry>
                <mesh filename="Bracket_U.obj"/>
            </geometry>
            <material name="dark_gray">
                <color rgba="0.4 0.4 0.4 1.0"/>
            </material>
        </visual>
        <collision>
            <geometry>
                <mesh filename="Bracket_U.obj"/>
            </geometry>
        </collision>
    </link>

    <!-- Joint connectiong Wrist Pitch Servo to U Bracket pitchs up and down [7] -->
    <joint name="WristPitchtoBracket" type="revolute">
        <parent link="Servo_WristPitch"/>
        <child link="Bracket_U"/>
        <origin xyz="0 0 0" rpy="0 0 0"/>
        <axis xyz="1.0 0.0 0.0"/>
        <limit lower="-1.57" upper="1.57" effort="1.0" velocity="1.0"/>
    </joint>

    <!-- Servo Wrist Roll Link [9] -->
    <link name="Servo_WristRoll">
        <inertial>
            <mass value="0.039"/>  <!-- Mass in kilograms -->
            <origin xyz="0 0 0" rpy="0 0 0"/>  <!-- Center of mass position (relative to link frame) -->
            <inertia ixx="0.01" ixy="0.0" ixz="0.0" iyy="0.01" iyz="0.0" izz="0.01"/>  <!-- Inertia matrix -->
        </inertial>
        <visual>
            <geometry>
                <mesh filename="Servo_WristRoll.obj"/>
            </geometry>
            <material name="dark_gray">
                <color rgba="0.4 0.4 0.4 1.0"/>
            </material>
        </visual>
        <collision>
            <geometry>
                <mesh filename="Servo_WristRoll.obj"/>
            </geometry>
        </collision>
    </link>

    <!-- Joint connectiong Wrist Bracket to  does not move relative to parent [8] -->
    <joint name="BrackettoWristRoll" type="fixed">
        <parent link="Bracket_U"/>
        <child link="Servo_WristRoll"/>
        <origin xyz="0 0 0.05" rpy="0 0 0"/>
    </joint>

    <!-- Servo Claw Base Link [10] -->
    <link name="Claw_Base">
        <inertial>
            <mass value="0.027"/>  <!-- Mass in kilograms -->
            <origin xyz="0 0 0" rpy="0 0 0"/>  <!-- Center of mass position (relative to link frame) -->
            <inertia ixx="0.01" ixy="0.0" ixz="0.0" iyy="0.01" iyz="0.0" izz="0.01"/>  <!-- Inertia matrix -->
        </inertial>
        <visual>
            <geometry>
                <mesh filename="Claw_Base.obj"/>
            </geometry>
            <material name="dark_gray">
                <color rgba="0.4 0.4 0.4 1.0"/>
            </material>
        </visual>
        <collision>
            <geometry>
                <mesh filename="Claw_Base.obj"/>
            </geometry>
        </collision>
    </link>

    <!-- Joint connectiong Wrist Roll Servo to Claw Base up and down [9] -->
    <joint name="WristRolltoClawBase" type="revolute">
        <parent link="Servo_WristRoll"/>
        <child link="Claw_Base"/>
        <origin xyz="-0.011 0 0.023" rpy="0 0 0"/>
        <axis xyz="0.0 0.0 1.0"/>
        <limit lower="-1.57" upper="1.57" effort="1.0" velocity="1.0"/>
    </joint>

    <!-- Servo Claw Base Link [11] -->
    <link name="Claw_Servo">
        <inertial>
            <mass value="0.039"/>  <!-- Mass in kilograms -->
            <origin xyz="0 0 0" rpy="0 0 0"/>  <!-- Center of mass position (relative to link frame) -->
            <inertia ixx="0.01" ixy="0.0" ixz="0.0" iyy="0.01" iyz="0.0" izz="0.01"/>  <!-- Inertia matrix -->
        </inertial>
        <visual>
            <geometry>
                <mesh filename="Claw_Servo.obj"/>
            </geometry>
            <material name="dark_gray">
                <color rgba="0.4 0.4 0.4 1.0"/>
            </material>
        </visual>
        <collision>
            <geometry>
                <mesh filename="Claw_Servo.obj"/>
            </geometry>
        </collision>
    </link>

    <!-- Joint connectiong Claw Base to Claw Servo does not move [10] -->
    <joint name="ClawBasetoClawServo" type="fixed">
        <parent link="Claw_Base"/>
        <child link="Claw_Servo"/>
        <origin xyz="0.005 0.031 0.03" rpy="0 0 0"/>
    </joint>

    <!-- Servo Claw Right Link [12] -->
    <link name="Claw_Right">
        <inertial>
            <mass value="0.025"/>  <!-- Mass in kilograms -->
            <origin xyz="0 0 0" rpy="0 0 0"/>  <!-- Center of mass position (relative to link frame) -->
            <inertia ixx="0.01" ixy="0.0" ixz="0.0" iyy="0.01" iyz="0.0" izz="0.01"/>  <!-- Inertia matrix -->
        </inertial>
        <visual>
            <geometry>
                <mesh filename="Claw_Right.obj"/>
            </geometry>
            <material name="dark_gray">
                <color rgba="0.4 0.4 0.4 1.0"/>
            </material>
        </visual>
        <collision>
            <geometry>
                <mesh filename="Claw_Right.obj"/>
            </geometry>
        </collision>
    </link>

    <!-- Joint connectiong Claw Base to Claw Servo does move [11] -->
    <joint name="ClawBasetoClawRight" type="revolute">
        <parent link="Claw_Base"/>
        <child link="Claw_Right"/>
        <origin xyz="-0.025 0.0 0.03" rpy="0 0 0"/>
        <axis xyz="0.0 1.0 0.0"/>
        <limit lower="-1.57" upper="1.57" effort="1.0" velocity="1.0"/>
    </joint>

    <!-- Servo Claw Left Link [13] -->
    <link name="Claw_Left">
        <inertial>
            <mass value="0.025"/>  <!-- Mass in kilograms -->
            <origin xyz="0 0 0" rpy="0 0 0"/>  <!-- Center of mass position (relative to link frame) -->
            <inertia ixx="0.01" ixy="0.0" ixz="0.0" iyy="0.01" iyz="0.0" izz="0.01"/>  <!-- Inertia matrix -->
        </inertial>
        <visual>
            <geometry>
                <mesh filename="Claw_Left.obj"/>
            </geometry>
            <material name="dark_gray">
                <color rgba="0.4 0.4 0.4 1.0"/>
            </material>
        </visual>
        <collision>
            <geometry>
                <mesh filename="Claw_Left.obj"/>
            </geometry>
        </collision>
    </link>

    <!-- Joint connectiong Claw Base to Claw Servo does move [12] -->
    <joint name="ClawBasetoClawLeft" type="revolute">
        <parent link="Claw_Base"/>
        <child link="Claw_Left"/>
        <origin xyz="0.005 0.0 0.03" rpy="0 0 0"/>
        <axis xyz="0.0 1.0 0.0"/>
        <limit lower="-1.57" upper="1.57" effort="1.0" velocity="1.0"/>
    </joint>

    <!-- Servo Claw Left Link [14] -->
    <link name="Claw_PadL">
        <inertial>
            <mass value="0.001"/>  <!-- Mass in kilograms -->
            <origin xyz="0 0 0" rpy="0 0 0"/>  <!-- Center of mass position (relative to link frame) -->
            <inertia ixx="0.01" ixy="0.0" ixz="0.0" iyy="0.01" iyz="0.0" izz="0.01"/>  <!-- Inertia matrix -->
        </inertial>
        <visual>
            <geometry>
                <mesh filename="Claw_PadL.obj"/>
            </geometry>
            <material name="dark_gray">
                <color rgba="0.4 0.4 0.4 1.0"/>
            </material>
        </visual>
        <collision>
            <geometry>
                <mesh filename="Claw_PadL.obj"/>
            </geometry>
        </collision>
    </link>

    <!-- Joint connectiong Claw Base to Claw Servo does not move [13] -->
    <joint name="ClawLefttoClawPad" type="fixed">
        <parent link="Claw_Left"/>
        <child link="Claw_PadL"/>
        <origin xyz="-0.0145 0.0 0.08" rpy="0 0 0"/>
    </joint>

    <!-- Servo Claw Left Link [15] -->
    <link name="Claw_PadR">
        <inertial>
            <mass value="0.001"/>  <!-- Mass in kilograms -->
            <origin xyz="0 0 0" rpy="0 0 0"/>  <!-- Center of mass position (relative to link frame) -->
            <inertia ixx="0.01" ixy="0.0" ixz="0.0" iyy="0.01" iyz="0.0" izz="0.01"/>  <!-- Inertia matrix -->
        </inertial>
        <visual>
            <geometry>
                <mesh filename="Claw_PadR.obj"/>
            </geometry>
            <material name="dark_gray">
                <color rgba="0.4 0.4 0.4 1.0"/>
            </material>
        </visual>
        <collision>
            <geometry>
                <mesh filename="Claw_PadR.obj"/>
            </geometry>
        </collision>
    </link>

    <!-- Joint connectiong Claw Base to Claw Servo does not move [14] -->
    <joint name="ClawRighttoClawPad" type="fixed">
        <parent link="Claw_Right"/>
        <child link="Claw_PadR"/>
        <origin xyz="0.0145 0.0 0.08" rpy="0 0 0"/>
    </joint>

    <!-- Servo Claw Left Link [16] -->
    <link name="Lidar_Base">
        <inertial>
            <mass value="0.001"/>  <!-- Mass in kilograms -->
            <origin xyz="0 0 0" rpy="0 0 0"/>  <!-- Center of mass position (relative to link frame) -->
            <inertia ixx="0.01" ixy="0.0" ixz="0.0" iyy="0.01" iyz="0.0" izz="0.01"/>  <!-- Inertia matrix -->
        </inertial>
        <visual>
            <geometry>
                <mesh filename="Lidar_Base.obj"/>
            </geometry>
            <material name="dark_gray">
                <color rgba="0.4 0.4 0.4 1.0"/>
            </material>
        </visual>
        <collision>
            <geometry>
                <mesh filename="Lidar_Base.obj"/>
            </geometry>
        </collision>
    </link>

    <!-- Joint connectiong Claw Base to Claw Servo does not move [15] -->
    <joint name="ClawServotoLidarBase" type="fixed">
        <parent link="Claw_Servo"/>
        <child link="Lidar_Base"/>
        <origin xyz="0.0125 0.005 0.0125" rpy="0 0 0"/>
    </joint>

    <!-- Servo Claw Left Link [17] -->
    <link name="Lidar_Lense">
        <inertial>
            <mass value="0.001"/>  <!-- Mass in kilograms -->
            <origin xyz="0 0 0" rpy="0 0 0"/>  <!-- Center of mass position (relative to link frame) -->
            <inertia ixx="0.01" ixy="0.0" ixz="0.0" iyy="0.01" iyz="0.0" izz="0.01"/>  <!-- Inertia matrix -->
        </inertial>
        <visual>
            <geometry>
                <mesh filename="Lidar_Lense.obj"/>
            </geometry>
            <material name="dark_gray">
                <color rgba="0.4 0.4 0.4 1.0"/>
            </material>
        </visual>
        <collision>
            <geometry>
                <mesh filename="Lidar_Lense.obj"/>
            </geometry>
        </collision>
    </link>

    <!-- Joint connectiong Claw Base to Claw Servo does not move [16] -->
    <joint name="LidarBasetoLidarLense" type="fixed">
        <parent link="Lidar_Base"/>
        <child link="Lidar_Lense"/>
        <origin xyz="0.0 0.0 0.0075" rpy="0 0 0"/>
    </joint>

    <!-- Servo Claw Left Link [18] -->
    <link name="Camera_Arm">
        <inertial>
            <mass value="0.123"/>  <!-- Mass in kilograms -->
            <origin xyz="0 0 0" rpy="0 0 0"/>  <!-- Center of mass position (relative to link frame) -->
            <inertia ixx="0.01" ixy="0.0" ixz="0.0" iyy="0.01" iyz="0.0" izz="0.01"/>  <!-- Inertia matrix -->
        </inertial>
        <visual>
            <geometry>
                <mesh filename="Camera_Arm.obj"/>
            </geometry>
            <material name="dark_gray">
                <color rgba="0.4 0.4 0.4 1.0"/>
            </material>
        </visual>
        <collision>
            <geometry>
                <mesh filename="Camera_Arm.obj"/>
            </geometry>
        </collision>
    </link>

    <!-- Joint connectiong Claw Base to Claw Servo does not move [17] -->
    <joint name="BaseWoodtoCameraArm" type="revolute">
        <parent link="Base_Wood"/>
        <child link="Camera_Arm"/>
        <origin xyz="0.123 -0.215 0.0075" rpy="0 0 0"/>
        <axis xyz="0.0 0.0 1.0"/>
        <limit lower="-1.57" upper="1.57" effort="1.0" velocity="1.0"/>
    </joint>

    <!-- Servo Claw Left Link [19] -->
    <link name="Camera_Mount">
        <inertial>
            <mass value="0.001"/>  <!-- Mass in kilograms -->
            <origin xyz="0 0 0" rpy="0 0 0"/>  <!-- Center of mass position (relative to link frame) -->
            <inertia ixx="0.01" ixy="0.0" ixz="0.0" iyy="0.01" iyz="0.0" izz="0.01"/>  <!-- Inertia matrix -->
        </inertial>
        <visual>
            <geometry>
                <mesh filename="Camera_Mount.obj"/>
            </geometry>
            <material name="dark_gray">
                <color rgba="0.4 0.4 0.4 1.0"/>
            </material>
        </visual>
        <collision>
            <geometry>
                <mesh filename="Camera_Mount.obj"/>
            </geometry>
        </collision>
    </link>

    <!-- Joint connectiong Claw Base to Claw Servo does not move [18] -->
    <joint name="CameraArmtoCameraMount" type="revolute">
        <parent link="Camera_Arm"/>
        <child link="Camera_Mount"/>
        <origin xyz="0.0 0.0 0.45" rpy="0 0 0"/>
        <axis xyz="1.0 0.0 0.0"/>
        <limit lower="-1.57" upper="1.57" effort="1.0" velocity="1.0"/>
    </joint>

    <!-- Servo Claw Left Link [20] -->
    <link name="Camera">
        <inertial>
            <mass value="0.001"/>  <!-- Mass in kilograms -->
            <origin xyz="0 0 0" rpy="0 0 0"/>  <!-- Center of mass position (relative to link frame) -->
            <inertia ixx="0.01" ixy="0.0" ixz="0.0" iyy="0.01" iyz="0.0" izz="0.01"/>  <!-- Inertia matrix -->
        </inertial>
        <visual>
            <geometry>
                <mesh filename="Camera.obj"/>
            </geometry>
            <material name="dark_gray">
                <color rgba="0.4 0.4 0.4 1.0"/>
            </material>
        </visual>
        <collision>
            <geometry>
                <mesh filename="Camera.obj"/>
            </geometry>
        </collision>
    </link>

    <!-- Joint connectiong Claw Base to Claw Servo does not move [19] -->
    <joint name="CameraMounttoCamera" type="fixed">
        <parent link="Camera_Mount"/>
        <child link="Camera"/>
        <origin xyz="0.0 0.0025 0.03" rpy="0 0 0"/>
    </joint>

</robot>